[2025-10-11T19:25:29.837+0000] {logging_mixin.py:151} INFO - Changing /opt/***/logs/dag_id=ETL_pipeline/run_id=manual__2025-10-11T19:25:27.286071+00:00/task_id=bronze_rig_count_pipeline permission to 509
[2025-10-11T19:25:29.838+0000] {logging_mixin.py:151} INFO - Failed to change /opt/***/logs/dag_id=ETL_pipeline/run_id=manual__2025-10-11T19:25:27.286071+00:00/task_id=bronze_rig_count_pipeline permission to 509: [Errno 1] Operation not permitted: '/opt/***/logs/dag_id=ETL_pipeline/run_id=manual__2025-10-11T19:25:27.286071+00:00/task_id=bronze_rig_count_pipeline'
[2025-10-11T19:25:29.882+0000] {logging_mixin.py:151} INFO - Changing /opt/***/logs/dag_id=ETL_pipeline/run_id=manual__2025-10-11T19:25:27.286071+00:00/task_id=bronze_rig_count_pipeline permission to 509
[2025-10-11T19:25:29.882+0000] {logging_mixin.py:151} INFO - Failed to change /opt/***/logs/dag_id=ETL_pipeline/run_id=manual__2025-10-11T19:25:27.286071+00:00/task_id=bronze_rig_count_pipeline permission to 509: [Errno 1] Operation not permitted: '/opt/***/logs/dag_id=ETL_pipeline/run_id=manual__2025-10-11T19:25:27.286071+00:00/task_id=bronze_rig_count_pipeline'
[2025-10-11T19:25:29.966+0000] {taskinstance.py:1157} INFO - Dependencies all met for dep_context=non-requeueable deps ti=<TaskInstance: ETL_pipeline.bronze_rig_count_pipeline manual__2025-10-11T19:25:27.286071+00:00 [queued]>
[2025-10-11T19:25:29.975+0000] {taskinstance.py:1157} INFO - Dependencies all met for dep_context=requeueable deps ti=<TaskInstance: ETL_pipeline.bronze_rig_count_pipeline manual__2025-10-11T19:25:27.286071+00:00 [queued]>
[2025-10-11T19:25:29.976+0000] {taskinstance.py:1359} INFO - Starting attempt 1 of 3
[2025-10-11T19:25:29.994+0000] {taskinstance.py:1380} INFO - Executing <Task(PythonOperator): bronze_rig_count_pipeline> on 2025-10-11 19:25:27.286071+00:00
[2025-10-11T19:25:30.007+0000] {standard_task_runner.py:57} INFO - Started process 2225 to run task
[2025-10-11T19:25:30.009+0000] {standard_task_runner.py:84} INFO - Running: ['***', 'tasks', 'run', 'ETL_pipeline', 'bronze_rig_count_pipeline', 'manual__2025-10-11T19:25:27.286071+00:00', '--job-id', '10', '--raw', '--subdir', 'DAGS_FOLDER/ETL_pipeline.py', '--cfg-path', '/tmp/tmpf50ev_v5']
[2025-10-11T19:25:30.016+0000] {standard_task_runner.py:85} INFO - Job 10: Subtask bronze_rig_count_pipeline
[2025-10-11T19:25:30.120+0000] {logging_mixin.py:151} INFO - Changing /opt/***/logs/dag_id=ETL_pipeline/run_id=manual__2025-10-11T19:25:27.286071+00:00/task_id=bronze_rig_count_pipeline permission to 509
[2025-10-11T19:25:30.121+0000] {logging_mixin.py:151} INFO - Failed to change /opt/***/logs/dag_id=ETL_pipeline/run_id=manual__2025-10-11T19:25:27.286071+00:00/task_id=bronze_rig_count_pipeline permission to 509: [Errno 1] Operation not permitted: '/opt/***/logs/dag_id=ETL_pipeline/run_id=manual__2025-10-11T19:25:27.286071+00:00/task_id=bronze_rig_count_pipeline'
[2025-10-11T19:25:30.125+0000] {task_command.py:415} INFO - Running <TaskInstance: ETL_pipeline.bronze_rig_count_pipeline manual__2025-10-11T19:25:27.286071+00:00 [running]> on host f22a895b55de
[2025-10-11T19:25:30.258+0000] {taskinstance.py:1660} INFO - Exporting env vars: AIRFLOW_CTX_DAG_OWNER='bech' AIRFLOW_CTX_DAG_ID='ETL_pipeline' AIRFLOW_CTX_TASK_ID='bronze_rig_count_pipeline' AIRFLOW_CTX_EXECUTION_DATE='2025-10-11T19:25:27.286071+00:00' AIRFLOW_CTX_TRY_NUMBER='1' AIRFLOW_CTX_DAG_RUN_ID='manual__2025-10-11T19:25:27.286071+00:00'
[2025-10-11T19:25:30.263+0000] {bronze_layer.py:123} INFO - Starting bronze layer data ingestion...
[2025-10-11T19:25:30.264+0000] {logging_mixin.py:151} INFO - Getting rig count data...
[2025-10-11T19:25:32.927+0000] {logging_mixin.py:151} WARNING - /home/***/.local/lib/python3.8/site-packages/openpyxl/worksheet/_reader.py:329 UserWarning: Unknown extension is not supported and will be removed
[2025-10-11T19:25:32.965+0000] {logging_mixin.py:151} INFO - Successfully loaded Excel file. Shape: (16503, 12)
[2025-10-11T19:25:32.977+0000] {base.py:73} INFO - Using connection ID 'oil_gas_conn' for task execution.
[2025-10-11T19:25:32.978+0000] {connection.py:314} INFO - Snowflake Connector for Python Version: 3.1.1, Python Version: 3.8.18, Platform: Linux-6.6.87.2-microsoft-standard-WSL2-x86_64-with-glibc2.2.5
[2025-10-11T19:25:32.991+0000] {bronze_layer.py:160} ERROR - Bronze layer ingestion failed: 251001: 251001: Account must be specified
[2025-10-11T19:25:32.991+0000] {taskinstance.py:1935} ERROR - Task failed with exception
Traceback (most recent call last):
  File "/home/airflow/.local/lib/python3.8/site-packages/airflow/operators/python.py", line 192, in execute
    return_value = self.execute_callable()
  File "/home/airflow/.local/lib/python3.8/site-packages/airflow/operators/python.py", line 209, in execute_callable
    return self.python_callable(*self.op_args, **self.op_kwargs)
  File "/opt/airflow/pipeline/bronze_layer.py", line 134, in bronze_etl
    sf_hook = create_snowflake_connection(SNOWFLAKE_CONN_ID)
  File "/opt/airflow/pipeline/bronze_layer.py", line 71, in create_snowflake_connection
    sf_hook.run("USE WAREHOUSE COMPUTE_WH")
  File "/home/airflow/.local/lib/python3.8/site-packages/airflow/providers/snowflake/hooks/snowflake.py", line 409, in run
    with closing(self.get_conn()) as conn:
  File "/home/airflow/.local/lib/python3.8/site-packages/airflow/providers/snowflake/hooks/snowflake.py", line 303, in get_conn
    conn = connector.connect(**conn_config)
  File "/home/airflow/.local/lib/python3.8/site-packages/snowflake/connector/__init__.py", line 51, in Connect
    return SnowflakeConnection(**kwargs)
  File "/home/airflow/.local/lib/python3.8/site-packages/snowflake/connector/connection.py", line 353, in __init__
    self.connect(**kwargs)
  File "/home/airflow/.local/lib/python3.8/site-packages/snowflake/connector/connection.py", line 597, in connect
    self.__config(**kwargs)
  File "/home/airflow/.local/lib/python3.8/site-packages/snowflake/connector/connection.py", line 1040, in __config
    Error.errorhandler_wrapper(
  File "/home/airflow/.local/lib/python3.8/site-packages/snowflake/connector/errors.py", line 290, in errorhandler_wrapper
    handed_over = Error.hand_to_other_handler(
  File "/home/airflow/.local/lib/python3.8/site-packages/snowflake/connector/errors.py", line 348, in hand_to_other_handler
    connection.errorhandler(connection, cursor, error_class, error_value)
  File "/home/airflow/.local/lib/python3.8/site-packages/snowflake/connector/errors.py", line 221, in default_errorhandler
    raise error_class(
snowflake.connector.errors.ProgrammingError: 251001: 251001: Account must be specified
[2025-10-11T19:25:33.001+0000] {taskinstance.py:1398} INFO - Marking task as UP_FOR_RETRY. dag_id=ETL_pipeline, task_id=bronze_rig_count_pipeline, execution_date=20251011T192527, start_date=20251011T192529, end_date=20251011T192533
[2025-10-11T19:25:33.012+0000] {standard_task_runner.py:104} ERROR - Failed to execute job 10 for task bronze_rig_count_pipeline (251001: 251001: Account must be specified; 2225)
[2025-10-11T19:25:33.077+0000] {local_task_job_runner.py:228} INFO - Task exited with return code 1
[2025-10-11T19:25:33.095+0000] {taskinstance.py:2776} INFO - 0 downstream tasks scheduled from follow-on schedule check
